[2022-12-26T11:19:48.554+0000] {taskinstance.py:1087} INFO - Dependencies all met for <TaskInstance: data_ingestion_to_cloud.download_file manual__2022-01-01T08:41:01+00:00 [queued]>
[2022-12-26T11:19:48.561+0000] {taskinstance.py:1087} INFO - Dependencies all met for <TaskInstance: data_ingestion_to_cloud.download_file manual__2022-01-01T08:41:01+00:00 [queued]>
[2022-12-26T11:19:48.563+0000] {taskinstance.py:1283} INFO - 
--------------------------------------------------------------------------------
[2022-12-26T11:19:48.564+0000] {taskinstance.py:1284} INFO - Starting attempt 7 of 7
[2022-12-26T11:19:48.564+0000] {taskinstance.py:1285} INFO - 
--------------------------------------------------------------------------------
[2022-12-26T11:19:48.573+0000] {taskinstance.py:1304} INFO - Executing <Task(PythonOperator): download_file> on 2022-01-01 08:41:01+00:00
[2022-12-26T11:19:48.580+0000] {standard_task_runner.py:55} INFO - Started process 10432 to run task
[2022-12-26T11:19:48.584+0000] {standard_task_runner.py:82} INFO - Running: ['***', 'tasks', 'run', 'data_ingestion_to_cloud', 'download_file', 'manual__2022-01-01T08:41:01+00:00', '--job-id', '26', '--raw', '--subdir', 'DAGS_FOLDER/ingestion_dag.py', '--cfg-path', '/tmp/tmph_ylh9ij']
[2022-12-26T11:19:48.587+0000] {standard_task_runner.py:83} INFO - Job 26: Subtask download_file
[2022-12-26T11:19:48.639+0000] {task_command.py:389} INFO - Running <TaskInstance: data_ingestion_to_cloud.download_file manual__2022-01-01T08:41:01+00:00 [running]> on host f33a20ab9138
[2022-12-26T11:19:48.686+0000] {taskinstance.py:1513} INFO - Exporting the following env vars:
AIRFLOW_CTX_DAG_OWNER=***
AIRFLOW_CTX_DAG_ID=data_ingestion_to_cloud
AIRFLOW_CTX_TASK_ID=download_file
AIRFLOW_CTX_EXECUTION_DATE=2022-01-01T08:41:01+00:00
AIRFLOW_CTX_TRY_NUMBER=7
AIRFLOW_CTX_DAG_RUN_ID=manual__2022-01-01T08:41:01+00:00
[2022-12-26T11:19:48.688+0000] {logging_mixin.py:137} INFO - 2022-01-01
[2022-12-26T11:19:49.875+0000] {taskinstance.py:1772} ERROR - Task failed with exception
Traceback (most recent call last):
  File "/home/airflow/.local/lib/python3.7/site-packages/airflow/operators/python.py", line 175, in execute
    return_value = self.execute_callable()
  File "/home/airflow/.local/lib/python3.7/site-packages/airflow/operators/python.py", line 192, in execute_callable
    return self.python_callable(*self.op_args, **self.op_kwargs)
  File "/opt/airflow/dags/ingestion.py", line 17, in download_file
    ti.xcom_push(key='filename', value=filename)
NameError: name 'ti' is not defined
[2022-12-26T11:19:49.893+0000] {taskinstance.py:1327} INFO - Marking task as FAILED. dag_id=data_ingestion_to_cloud, task_id=download_file, execution_date=20220101T084101, start_date=20221226T111948, end_date=20221226T111949
[2022-12-26T11:19:49.919+0000] {standard_task_runner.py:105} ERROR - Failed to execute job 26 for task download_file (name 'ti' is not defined; 10432)
[2022-12-26T11:19:49.967+0000] {local_task_job.py:159} INFO - Task exited with return code 1
[2022-12-26T11:19:49.991+0000] {taskinstance.py:2582} INFO - 0 downstream tasks scheduled from follow-on schedule check
