[2022-12-26T08:51:23.150+0000] {taskinstance.py:1087} INFO - Dependencies all met for <TaskInstance: data_ingestion_to_cloud.download_file manual__2022-01-01T08:41:01+00:00 [queued]>
[2022-12-26T08:51:23.156+0000] {taskinstance.py:1087} INFO - Dependencies all met for <TaskInstance: data_ingestion_to_cloud.download_file manual__2022-01-01T08:41:01+00:00 [queued]>
[2022-12-26T08:51:23.157+0000] {taskinstance.py:1283} INFO - 
--------------------------------------------------------------------------------
[2022-12-26T08:51:23.158+0000] {taskinstance.py:1284} INFO - Starting attempt 2 of 2
[2022-12-26T08:51:23.158+0000] {taskinstance.py:1285} INFO - 
--------------------------------------------------------------------------------
[2022-12-26T08:51:23.167+0000] {taskinstance.py:1304} INFO - Executing <Task(PythonOperator): download_file> on 2022-01-01 08:41:01+00:00
[2022-12-26T08:51:23.173+0000] {standard_task_runner.py:55} INFO - Started process 812 to run task
[2022-12-26T08:51:23.178+0000] {standard_task_runner.py:82} INFO - Running: ['***', 'tasks', 'run', 'data_ingestion_to_cloud', 'download_file', 'manual__2022-01-01T08:41:01+00:00', '--job-id', '19', '--raw', '--subdir', 'DAGS_FOLDER/ingestion_dag.py', '--cfg-path', '/tmp/tmph4okgv5r']
[2022-12-26T08:51:23.182+0000] {standard_task_runner.py:83} INFO - Job 19: Subtask download_file
[2022-12-26T08:51:23.257+0000] {task_command.py:389} INFO - Running <TaskInstance: data_ingestion_to_cloud.download_file manual__2022-01-01T08:41:01+00:00 [running]> on host f33a20ab9138
[2022-12-26T08:51:23.314+0000] {taskinstance.py:1513} INFO - Exporting the following env vars:
AIRFLOW_CTX_DAG_OWNER=***
AIRFLOW_CTX_DAG_ID=data_ingestion_to_cloud
AIRFLOW_CTX_TASK_ID=download_file
AIRFLOW_CTX_EXECUTION_DATE=2022-01-01T08:41:01+00:00
AIRFLOW_CTX_TRY_NUMBER=2
AIRFLOW_CTX_DAG_RUN_ID=manual__2022-01-01T08:41:01+00:00
[2022-12-26T08:51:23.322+0000] {taskinstance.py:1772} ERROR - Task failed with exception
Traceback (most recent call last):
  File "/home/airflow/.local/lib/python3.7/site-packages/airflow/operators/python.py", line 175, in execute
    return_value = self.execute_callable()
  File "/home/airflow/.local/lib/python3.7/site-packages/airflow/operators/python.py", line 192, in execute_callable
    return self.python_callable(*self.op_args, **self.op_kwargs)
  File "/opt/airflow/dags/ingestion.py", line 6, in download_file
    instance_date = datetime.strptime(instance_date, '%Y-%m-%d').date()
  File "/usr/local/lib/python3.7/_strptime.py", line 577, in _strptime_datetime
    tt, fraction, gmtoff_fraction = _strptime(data_string, format)
  File "/usr/local/lib/python3.7/_strptime.py", line 359, in _strptime
    (data_string, format))
ValueError: time data 'instance_date' does not match format '%Y-%m-%d'
[2022-12-26T08:51:23.331+0000] {taskinstance.py:1327} INFO - Marking task as FAILED. dag_id=data_ingestion_to_cloud, task_id=download_file, execution_date=20220101T084101, start_date=20221226T085123, end_date=20221226T085123
[2022-12-26T08:51:23.340+0000] {standard_task_runner.py:105} ERROR - Failed to execute job 19 for task download_file (time data 'instance_date' does not match format '%Y-%m-%d'; 812)
[2022-12-26T08:51:23.356+0000] {local_task_job.py:159} INFO - Task exited with return code 1
[2022-12-26T08:51:23.371+0000] {taskinstance.py:2582} INFO - 0 downstream tasks scheduled from follow-on schedule check
