[2022-12-26T09:11:22.398+0000] {taskinstance.py:1087} INFO - Dependencies all met for <TaskInstance: data_ingestion_to_cloud.download_file manual__2022-01-01T08:41:01+00:00 [queued]>
[2022-12-26T09:11:22.404+0000] {taskinstance.py:1087} INFO - Dependencies all met for <TaskInstance: data_ingestion_to_cloud.download_file manual__2022-01-01T08:41:01+00:00 [queued]>
[2022-12-26T09:11:22.405+0000] {taskinstance.py:1283} INFO - 
--------------------------------------------------------------------------------
[2022-12-26T09:11:22.405+0000] {taskinstance.py:1284} INFO - Starting attempt 3 of 3
[2022-12-26T09:11:22.406+0000] {taskinstance.py:1285} INFO - 
--------------------------------------------------------------------------------
[2022-12-26T09:11:22.414+0000] {taskinstance.py:1304} INFO - Executing <Task(PythonOperator): download_file> on 2022-01-01 08:41:01+00:00
[2022-12-26T09:11:22.420+0000] {standard_task_runner.py:55} INFO - Started process 2113 to run task
[2022-12-26T09:11:22.425+0000] {standard_task_runner.py:82} INFO - Running: ['***', 'tasks', 'run', 'data_ingestion_to_cloud', 'download_file', 'manual__2022-01-01T08:41:01+00:00', '--job-id', '20', '--raw', '--subdir', 'DAGS_FOLDER/ingestion_dag.py', '--cfg-path', '/tmp/tmp_22zznmb']
[2022-12-26T09:11:22.429+0000] {standard_task_runner.py:83} INFO - Job 20: Subtask download_file
[2022-12-26T09:11:22.492+0000] {task_command.py:389} INFO - Running <TaskInstance: data_ingestion_to_cloud.download_file manual__2022-01-01T08:41:01+00:00 [running]> on host f33a20ab9138
[2022-12-26T09:11:22.539+0000] {taskinstance.py:1513} INFO - Exporting the following env vars:
AIRFLOW_CTX_DAG_OWNER=***
AIRFLOW_CTX_DAG_ID=data_ingestion_to_cloud
AIRFLOW_CTX_TASK_ID=download_file
AIRFLOW_CTX_EXECUTION_DATE=2022-01-01T08:41:01+00:00
AIRFLOW_CTX_TRY_NUMBER=3
AIRFLOW_CTX_DAG_RUN_ID=manual__2022-01-01T08:41:01+00:00
[2022-12-26T09:11:22.540+0000] {logging_mixin.py:137} INFO - instance_date
[2022-12-26T09:11:22.544+0000] {taskinstance.py:1772} ERROR - Task failed with exception
Traceback (most recent call last):
  File "/home/airflow/.local/lib/python3.7/site-packages/airflow/operators/python.py", line 175, in execute
    return_value = self.execute_callable()
  File "/home/airflow/.local/lib/python3.7/site-packages/airflow/operators/python.py", line 192, in execute_callable
    return self.python_callable(*self.op_args, **self.op_kwargs)
  File "/opt/airflow/dags/ingestion.py", line 7, in download_file
    instance_date = datetime.strptime(instance_date, '%Y-%m-%d').date()
  File "/usr/local/lib/python3.7/_strptime.py", line 577, in _strptime_datetime
    tt, fraction, gmtoff_fraction = _strptime(data_string, format)
  File "/usr/local/lib/python3.7/_strptime.py", line 359, in _strptime
    (data_string, format))
ValueError: time data 'instance_date' does not match format '%Y-%m-%d'
[2022-12-26T09:11:22.553+0000] {taskinstance.py:1327} INFO - Marking task as FAILED. dag_id=data_ingestion_to_cloud, task_id=download_file, execution_date=20220101T084101, start_date=20221226T091122, end_date=20221226T091122
[2022-12-26T09:11:22.562+0000] {standard_task_runner.py:105} ERROR - Failed to execute job 20 for task download_file (time data 'instance_date' does not match format '%Y-%m-%d'; 2113)
[2022-12-26T09:11:22.596+0000] {local_task_job.py:159} INFO - Task exited with return code 1
[2022-12-26T09:11:22.610+0000] {taskinstance.py:2582} INFO - 0 downstream tasks scheduled from follow-on schedule check
