[2022-12-26T08:41:20.785+0000] {taskinstance.py:1087} INFO - Dependencies all met for <TaskInstance: data_ingestion_to_cloud.download_file manual__2022-01-01T08:41:01+00:00 [queued]>
[2022-12-26T08:41:20.791+0000] {taskinstance.py:1087} INFO - Dependencies all met for <TaskInstance: data_ingestion_to_cloud.download_file manual__2022-01-01T08:41:01+00:00 [queued]>
[2022-12-26T08:41:20.792+0000] {taskinstance.py:1283} INFO - 
--------------------------------------------------------------------------------
[2022-12-26T08:41:20.792+0000] {taskinstance.py:1284} INFO - Starting attempt 1 of 1
[2022-12-26T08:41:20.793+0000] {taskinstance.py:1285} INFO - 
--------------------------------------------------------------------------------
[2022-12-26T08:41:20.800+0000] {taskinstance.py:1304} INFO - Executing <Task(PythonOperator): download_file> on 2022-01-01 08:41:01+00:00
[2022-12-26T08:41:20.806+0000] {standard_task_runner.py:55} INFO - Started process 160 to run task
[2022-12-26T08:41:20.810+0000] {standard_task_runner.py:82} INFO - Running: ['***', 'tasks', 'run', 'data_ingestion_to_cloud', 'download_file', 'manual__2022-01-01T08:41:01+00:00', '--job-id', '18', '--raw', '--subdir', 'DAGS_FOLDER/ingestion_dag.py', '--cfg-path', '/tmp/tmpnfa95d77']
[2022-12-26T08:41:20.813+0000] {standard_task_runner.py:83} INFO - Job 18: Subtask download_file
[2022-12-26T08:41:20.870+0000] {task_command.py:389} INFO - Running <TaskInstance: data_ingestion_to_cloud.download_file manual__2022-01-01T08:41:01+00:00 [running]> on host f33a20ab9138
[2022-12-26T08:41:20.894+0000] {abstractoperator.py:596} ERROR - Exception rendering Jinja template for task 'download_file', field 'op_args'. Template: {'instance_date': '{{ TaskInstance.start_date }}'}
Traceback (most recent call last):
  File "/home/airflow/.local/lib/python3.7/site-packages/airflow/models/abstractoperator.py", line 589, in _do_render_template_fields
    seen_oids,
  File "/home/airflow/.local/lib/python3.7/site-packages/airflow/models/abstractoperator.py", line 659, in render_template
    return {k: self.render_template(v, context, jinja_env, oids) for k, v in value.items()}
  File "/home/airflow/.local/lib/python3.7/site-packages/airflow/models/abstractoperator.py", line 659, in <dictcomp>
    return {k: self.render_template(v, context, jinja_env, oids) for k, v in value.items()}
  File "/home/airflow/.local/lib/python3.7/site-packages/airflow/models/abstractoperator.py", line 646, in render_template
    return render_template_to_string(template, context)
  File "/home/airflow/.local/lib/python3.7/site-packages/airflow/utils/helpers.py", line 288, in render_template_to_string
    return render_template(template, cast(MutableMapping[str, Any], context), native=False)
  File "/home/airflow/.local/lib/python3.7/site-packages/airflow/utils/helpers.py", line 283, in render_template
    return "".join(nodes)
  File "<template>", line 12, in root
  File "/home/airflow/.local/lib/python3.7/site-packages/jinja2/sandbox.py", line 326, in getattr
    value = getattr(obj, attribute)
  File "/home/airflow/.local/lib/python3.7/site-packages/jinja2/runtime.py", line 859, in __getattr__
    return self._fail_with_undefined_error()
  File "/home/airflow/.local/lib/python3.7/site-packages/jinja2/runtime.py", line 852, in _fail_with_undefined_error
    raise self._undefined_exception(self._undefined_message)
jinja2.exceptions.UndefinedError: 'TaskInstance' is undefined
[2022-12-26T08:41:20.896+0000] {taskinstance.py:1772} ERROR - Task failed with exception
Traceback (most recent call last):
  File "/home/airflow/.local/lib/python3.7/site-packages/airflow/models/taskinstance.py", line 1378, in _run_raw_task
    self._execute_task_with_callbacks(context, test_mode)
  File "/home/airflow/.local/lib/python3.7/site-packages/airflow/models/taskinstance.py", line 1497, in _execute_task_with_callbacks
    task_orig = self.render_templates(context=context)
  File "/home/airflow/.local/lib/python3.7/site-packages/airflow/models/taskinstance.py", line 2119, in render_templates
    original_task.render_template_fields(context)
  File "/home/airflow/.local/lib/python3.7/site-packages/airflow/models/baseoperator.py", line 1196, in render_template_fields
    self._do_render_template_fields(self, self.template_fields, context, jinja_env, set())
  File "/home/airflow/.local/lib/python3.7/site-packages/airflow/utils/session.py", line 75, in wrapper
    return func(*args, session=session, **kwargs)
  File "/home/airflow/.local/lib/python3.7/site-packages/airflow/models/abstractoperator.py", line 589, in _do_render_template_fields
    seen_oids,
  File "/home/airflow/.local/lib/python3.7/site-packages/airflow/models/abstractoperator.py", line 659, in render_template
    return {k: self.render_template(v, context, jinja_env, oids) for k, v in value.items()}
  File "/home/airflow/.local/lib/python3.7/site-packages/airflow/models/abstractoperator.py", line 659, in <dictcomp>
    return {k: self.render_template(v, context, jinja_env, oids) for k, v in value.items()}
  File "/home/airflow/.local/lib/python3.7/site-packages/airflow/models/abstractoperator.py", line 646, in render_template
    return render_template_to_string(template, context)
  File "/home/airflow/.local/lib/python3.7/site-packages/airflow/utils/helpers.py", line 288, in render_template_to_string
    return render_template(template, cast(MutableMapping[str, Any], context), native=False)
  File "/home/airflow/.local/lib/python3.7/site-packages/airflow/utils/helpers.py", line 283, in render_template
    return "".join(nodes)
  File "<template>", line 12, in root
  File "/home/airflow/.local/lib/python3.7/site-packages/jinja2/sandbox.py", line 326, in getattr
    value = getattr(obj, attribute)
  File "/home/airflow/.local/lib/python3.7/site-packages/jinja2/runtime.py", line 859, in __getattr__
    return self._fail_with_undefined_error()
  File "/home/airflow/.local/lib/python3.7/site-packages/jinja2/runtime.py", line 852, in _fail_with_undefined_error
    raise self._undefined_exception(self._undefined_message)
jinja2.exceptions.UndefinedError: 'TaskInstance' is undefined
[2022-12-26T08:41:20.906+0000] {taskinstance.py:1327} INFO - Marking task as FAILED. dag_id=data_ingestion_to_cloud, task_id=download_file, execution_date=20220101T084101, start_date=20221226T084120, end_date=20221226T084120
[2022-12-26T08:41:20.913+0000] {standard_task_runner.py:105} ERROR - Failed to execute job 18 for task download_file ('TaskInstance' is undefined; 160)
[2022-12-26T08:41:20.942+0000] {local_task_job.py:159} INFO - Task exited with return code 1
[2022-12-26T08:41:20.957+0000] {taskinstance.py:2582} INFO - 0 downstream tasks scheduled from follow-on schedule check
