[2022-12-26T12:33:50.623+0000] {taskinstance.py:1087} INFO - Dependencies all met for <TaskInstance: data_ingestion_to_cloud.upload_file_to_gcs manual__2022-01-01T08:41:01+00:00 [queued]>
[2022-12-26T12:33:50.629+0000] {taskinstance.py:1087} INFO - Dependencies all met for <TaskInstance: data_ingestion_to_cloud.upload_file_to_gcs manual__2022-01-01T08:41:01+00:00 [queued]>
[2022-12-26T12:33:50.630+0000] {taskinstance.py:1283} INFO - 
--------------------------------------------------------------------------------
[2022-12-26T12:33:50.630+0000] {taskinstance.py:1284} INFO - Starting attempt 9 of 9
[2022-12-26T12:33:50.631+0000] {taskinstance.py:1285} INFO - 
--------------------------------------------------------------------------------
[2022-12-26T12:33:50.638+0000] {taskinstance.py:1304} INFO - Executing <Task(PythonOperator): upload_file_to_gcs> on 2022-01-01 08:41:01+00:00
[2022-12-26T12:33:50.644+0000] {standard_task_runner.py:55} INFO - Started process 223 to run task
[2022-12-26T12:33:50.649+0000] {standard_task_runner.py:82} INFO - Running: ['***', 'tasks', 'run', 'data_ingestion_to_cloud', 'upload_file_to_gcs', 'manual__2022-01-01T08:41:01+00:00', '--job-id', '45', '--raw', '--subdir', 'DAGS_FOLDER/ingestion_dag.py', '--cfg-path', '/tmp/tmpgid5kadr']
[2022-12-26T12:33:50.652+0000] {standard_task_runner.py:83} INFO - Job 45: Subtask upload_file_to_gcs
[2022-12-26T12:33:50.710+0000] {task_command.py:389} INFO - Running <TaskInstance: data_ingestion_to_cloud.upload_file_to_gcs manual__2022-01-01T08:41:01+00:00 [running]> on host 630310be3161
[2022-12-26T12:33:50.764+0000] {taskinstance.py:1513} INFO - Exporting the following env vars:
AIRFLOW_CTX_DAG_OWNER=***
AIRFLOW_CTX_DAG_ID=data_ingestion_to_cloud
AIRFLOW_CTX_TASK_ID=upload_file_to_gcs
AIRFLOW_CTX_EXECUTION_DATE=2022-01-01T08:41:01+00:00
AIRFLOW_CTX_TRY_NUMBER=9
AIRFLOW_CTX_DAG_RUN_ID=manual__2022-01-01T08:41:01+00:00
[2022-12-26T12:33:50.799+0000] {taskinstance.py:1772} ERROR - Task failed with exception
Traceback (most recent call last):
  File "/home/airflow/.local/lib/python3.7/site-packages/airflow/operators/python.py", line 175, in execute
    return_value = self.execute_callable()
  File "/home/airflow/.local/lib/python3.7/site-packages/airflow/operators/python.py", line 192, in execute_callable
    return self.python_callable(*self.op_args, **self.op_kwargs)
  File "/opt/airflow/dags/ingestion.py", line 35, in upload_file_to_gcs
    blob.upload_from_filename(filename)
  File "/home/airflow/.local/lib/python3.7/site-packages/google/cloud/storage/blob.py", line 2679, in upload_from_filename
    content_type = self._get_content_type(content_type, filename=filename)
  File "/home/airflow/.local/lib/python3.7/site-packages/google/cloud/storage/blob.py", line 1660, in _get_content_type
    content_type, _ = mimetypes.guess_type(filename)
  File "/usr/local/lib/python3.7/mimetypes.py", line 292, in guess_type
    return _db.guess_type(url, strict)
  File "/usr/local/lib/python3.7/mimetypes.py", line 116, in guess_type
    url = os.fspath(url)
TypeError: expected str, bytes or os.PathLike object, not LazyXComAccess
[2022-12-26T12:33:50.805+0000] {taskinstance.py:1327} INFO - Marking task as FAILED. dag_id=data_ingestion_to_cloud, task_id=upload_file_to_gcs, execution_date=20220101T084101, start_date=20221226T123350, end_date=20221226T123350
[2022-12-26T12:33:50.813+0000] {standard_task_runner.py:105} ERROR - Failed to execute job 45 for task upload_file_to_gcs (expected str, bytes or os.PathLike object, not LazyXComAccess; 223)
[2022-12-26T12:33:50.861+0000] {local_task_job.py:159} INFO - Task exited with return code 1
[2022-12-26T12:33:50.876+0000] {taskinstance.py:2582} INFO - 0 downstream tasks scheduled from follow-on schedule check
