[2022-12-26T11:19:48.562+0000] {taskinstance.py:1081} INFO - Dependencies not met for <TaskInstance: data_ingestion_to_cloud.upload_file_to_gcs manual__2022-01-01T08:41:01+00:00 [queued]>, dependency 'Trigger Rule' FAILED: Task's trigger rule 'all_success' requires all upstream tasks to have succeeded, but found 1 non-success(es). upstream_states=_UpstreamTIStates(success=0, skipped=0, failed=0, upstream_failed=0, removed=0, done=0), upstream_task_ids={'download_file'}
[2022-12-26T11:19:48.564+0000] {local_task_job.py:98} INFO - Task is not able to be run
[2022-12-26T11:31:38.528+0000] {taskinstance.py:1087} INFO - Dependencies all met for <TaskInstance: data_ingestion_to_cloud.upload_file_to_gcs manual__2022-01-01T08:41:01+00:00 [queued]>
[2022-12-26T11:31:38.536+0000] {taskinstance.py:1087} INFO - Dependencies all met for <TaskInstance: data_ingestion_to_cloud.upload_file_to_gcs manual__2022-01-01T08:41:01+00:00 [queued]>
[2022-12-26T11:31:38.537+0000] {taskinstance.py:1283} INFO - 
--------------------------------------------------------------------------------
[2022-12-26T11:31:38.538+0000] {taskinstance.py:1284} INFO - Starting attempt 2 of 2
[2022-12-26T11:31:38.539+0000] {taskinstance.py:1285} INFO - 
--------------------------------------------------------------------------------
[2022-12-26T11:31:38.548+0000] {taskinstance.py:1304} INFO - Executing <Task(PythonOperator): upload_file_to_gcs> on 2022-01-01 08:41:01+00:00
[2022-12-26T11:31:38.553+0000] {standard_task_runner.py:55} INFO - Started process 11216 to run task
[2022-12-26T11:31:38.557+0000] {standard_task_runner.py:82} INFO - Running: ['***', 'tasks', 'run', 'data_ingestion_to_cloud', 'upload_file_to_gcs', 'manual__2022-01-01T08:41:01+00:00', '--job-id', '30', '--raw', '--subdir', 'DAGS_FOLDER/ingestion_dag.py', '--cfg-path', '/tmp/tmpuulucizi']
[2022-12-26T11:31:38.560+0000] {standard_task_runner.py:83} INFO - Job 30: Subtask upload_file_to_gcs
[2022-12-26T11:31:38.685+0000] {task_command.py:389} INFO - Running <TaskInstance: data_ingestion_to_cloud.upload_file_to_gcs manual__2022-01-01T08:41:01+00:00 [running]> on host f33a20ab9138
[2022-12-26T11:31:38.732+0000] {taskinstance.py:1513} INFO - Exporting the following env vars:
AIRFLOW_CTX_DAG_OWNER=***
AIRFLOW_CTX_DAG_ID=data_ingestion_to_cloud
AIRFLOW_CTX_TASK_ID=upload_file_to_gcs
AIRFLOW_CTX_EXECUTION_DATE=2022-01-01T08:41:01+00:00
AIRFLOW_CTX_TRY_NUMBER=2
AIRFLOW_CTX_DAG_RUN_ID=manual__2022-01-01T08:41:01+00:00
[2022-12-26T11:31:38.733+0000] {taskinstance.py:1772} ERROR - Task failed with exception
Traceback (most recent call last):
  File "/home/airflow/.local/lib/python3.7/site-packages/airflow/operators/python.py", line 175, in execute
    return_value = self.execute_callable()
  File "/home/airflow/.local/lib/python3.7/site-packages/airflow/operators/python.py", line 192, in execute_callable
    return self.python_callable(*self.op_args, **self.op_kwargs)
TypeError: upload_file_to_gcs() missing 1 required positional argument: 'filename'
[2022-12-26T11:31:38.742+0000] {taskinstance.py:1327} INFO - Marking task as FAILED. dag_id=data_ingestion_to_cloud, task_id=upload_file_to_gcs, execution_date=20220101T084101, start_date=20221226T113138, end_date=20221226T113138
[2022-12-26T11:31:38.749+0000] {standard_task_runner.py:105} ERROR - Failed to execute job 30 for task upload_file_to_gcs (upload_file_to_gcs() missing 1 required positional argument: 'filename'; 11216)
[2022-12-26T11:31:38.790+0000] {local_task_job.py:159} INFO - Task exited with return code 1
[2022-12-26T11:31:38.805+0000] {taskinstance.py:2582} INFO - 0 downstream tasks scheduled from follow-on schedule check
