[2022-12-26T11:18:46.106+0000] {taskinstance.py:1087} INFO - Dependencies all met for <TaskInstance: data_ingestion_to_cloud.upload_file_to_gcs manual__2022-01-01T08:41:01+00:00 [queued]>
[2022-12-26T11:18:46.112+0000] {taskinstance.py:1087} INFO - Dependencies all met for <TaskInstance: data_ingestion_to_cloud.upload_file_to_gcs manual__2022-01-01T08:41:01+00:00 [queued]>
[2022-12-26T11:18:46.113+0000] {taskinstance.py:1283} INFO - 
--------------------------------------------------------------------------------
[2022-12-26T11:18:46.114+0000] {taskinstance.py:1284} INFO - Starting attempt 1 of 1
[2022-12-26T11:18:46.115+0000] {taskinstance.py:1285} INFO - 
--------------------------------------------------------------------------------
[2022-12-26T11:18:46.125+0000] {taskinstance.py:1304} INFO - Executing <Task(PythonOperator): upload_file_to_gcs> on 2022-01-01 08:41:01+00:00
[2022-12-26T11:18:46.131+0000] {standard_task_runner.py:55} INFO - Started process 10366 to run task
[2022-12-26T11:18:46.142+0000] {standard_task_runner.py:82} INFO - Running: ['***', 'tasks', 'run', 'data_ingestion_to_cloud', 'upload_file_to_gcs', 'manual__2022-01-01T08:41:01+00:00', '--job-id', '25', '--raw', '--subdir', 'DAGS_FOLDER/ingestion_dag.py', '--cfg-path', '/tmp/tmpm985qe05']
[2022-12-26T11:18:46.145+0000] {standard_task_runner.py:83} INFO - Job 25: Subtask upload_file_to_gcs
[2022-12-26T11:18:46.236+0000] {task_command.py:389} INFO - Running <TaskInstance: data_ingestion_to_cloud.upload_file_to_gcs manual__2022-01-01T08:41:01+00:00 [running]> on host f33a20ab9138
[2022-12-26T11:18:46.296+0000] {taskinstance.py:1513} INFO - Exporting the following env vars:
AIRFLOW_CTX_DAG_OWNER=***
AIRFLOW_CTX_DAG_ID=data_ingestion_to_cloud
AIRFLOW_CTX_TASK_ID=upload_file_to_gcs
AIRFLOW_CTX_EXECUTION_DATE=2022-01-01T08:41:01+00:00
AIRFLOW_CTX_TRY_NUMBER=1
AIRFLOW_CTX_DAG_RUN_ID=manual__2022-01-01T08:41:01+00:00
[2022-12-26T11:18:46.298+0000] {taskinstance.py:1772} ERROR - Task failed with exception
Traceback (most recent call last):
  File "/home/airflow/.local/lib/python3.7/site-packages/airflow/operators/python.py", line 175, in execute
    return_value = self.execute_callable()
  File "/home/airflow/.local/lib/python3.7/site-packages/airflow/operators/python.py", line 192, in execute_callable
    return self.python_callable(*self.op_args, **self.op_kwargs)
TypeError: upload_to_gcs() missing 1 required positional argument: 'filename'
[2022-12-26T11:18:46.308+0000] {taskinstance.py:1327} INFO - Marking task as FAILED. dag_id=data_ingestion_to_cloud, task_id=upload_file_to_gcs, execution_date=20220101T084101, start_date=20221226T111846, end_date=20221226T111846
[2022-12-26T11:18:46.317+0000] {standard_task_runner.py:105} ERROR - Failed to execute job 25 for task upload_file_to_gcs (upload_to_gcs() missing 1 required positional argument: 'filename'; 10366)
[2022-12-26T11:18:46.348+0000] {local_task_job.py:159} INFO - Task exited with return code 1
[2022-12-26T11:18:46.363+0000] {taskinstance.py:2582} INFO - 0 downstream tasks scheduled from follow-on schedule check
